Workbook

Sheet Sheet3
A3: Row Labels | B3: Sum of Sales
A4: 1/13/2014 | B4: 3553.795
A5: 1/13/2015 | B5: 622.278
A6: 1/13/2017 | B6: 4619.33
A7: 1/14/2014 | B7: 61.96
A8: 1/14/2016 | B8: 405.344
A9: 1/14/2017 | B9: 1056.038
A10: 1/15/2014 | B10: 149.95
A11: 1/15/2016 | B11: 701.923
A12: 1/15/2017 | B12: 2140.28
A13: 1/16/2014 | B13: 299.964
A14: 1/16/2016 | B14: 102.218
A15: 1/16/2017 | B15: 6230.292
... A757: 9/30/2017 | B757: 540.76
A758: 41641 | B758: 468.9
A759: 41642 | B759: 2203.151
A760: 41643 | B760: 119.888
A761: 41645 | B761: 5188.52
A762: 41646 | B762: 601.024
A763: 41647 | B763: 228.328
A764: 41648 | B764: 469.436
A765: 41649 | B765: 4.71
A766: 41650 | B766: 4732.08
A767: 41651 | B767: 5624.39
A768: 41672 | B768: 211.646
A769: 41673 | B769: 202.384
... A1240: 43080 | B1240: 2911.386
A1241: Grand Total | B1241: 2297200.9

Sheet Sheet1
A1: Row ID | B1: Order ID | C1: Order Date | D1: Ship Date | E1: Ship Mode | F1: Customer ID | G1: Customer Name | H1: Segment | I1: Country | J1: City | K1: State | L1: Postal Code | M1: Region | N1: Product ID | O1: Category | P1: Sub-Category | Q1: Product Name | R1: Sales | S1: Quantity | T1: Discount | U1: Profit | V1: Corrected Date
A2: 1 | B2: CA-2016-152156 | C2: 42593 | D2: 42685 | E2: Second Class | F2: CG-12520 | G2: Claire Gute | H2: Consumer | I2: United States | J2: Henderson | K2: Kentucky | L2: 42420 | M2: South | N2: FUR-BO-10001798 | O2: Furniture | P2: Bookcases | Q2: Bush Somerset Collection Bookcase | R2: 261.96 | S2: 2 | T2: 0 | U2: 41.9136 | V2: =IFERROR(IF(ISNUMBER(C2),C2,DATEVALUE(C2)),"CHECK DATE") -> 42593
A3: 2 | B3: CA-2016-152156 | C3: 42593 | D3: 42685 | E3: Second Class | F3: CG-12520 | G3: Claire Gute | H3: Consumer | I3: United States | J3: Henderson | K3: Kentucky | L3: 42420 | M3: South | N3: FUR-CH-10000454 | O3: Furniture | P3: Chairs | Q3: Hon Deluxe Fabric Upholstered Stacking Chairs, Rounded Back | R3: 731.94 | S3: 3 | T3: 0 | U3: 219.582 | V3: =IFERROR(IF(ISNUMBER(C3),C3,DATEVALUE(C3)),"CHECK DATE") -> 42593
A4: 3 | B4: CA-2016-138688 | C4: 42710 | D4: 6/16/2016 | E4: Second Class | F4: DV-13045 | G4: Darrin Van Huff | H4: Corporate | I4: United States | J4: Los Angeles | K4: California | L4: 90036 | M4: West | N4: OFF-LA-10000240 | O4: Office Supplies | P4: Labels | Q4: Self-Adhesive Address Labels for Typewriters by Universal | R4: 14.62 | S4: 2 | T4: 0 | U4: 6.8714 | V4: =IFERROR(IF(ISNUMBER(C4),C4,DATEVALUE(C4)),"CHECK DATE") -> 42710
A5: 4 | B5: US-2015-108966 | C5: 42318 | D5: 10/18/2015 | E5: Standard Class | F5: SO-20335 | G5: Sean O'Donnell | H5: Consumer | I5: United States | J5: Fort Lauderdale | K5: Florida | L5: 33311 | M5: South | N5: FUR-TA-10000577 | O5: Furniture | P5: Tables | Q5: Bretford CR4500 Series Slim Rectangular Table | R5: 957.5775 | S5: 5 | T5: 0.45 | U5: -383.031 | V5: =IFERROR(IF(ISNUMBER(C5),C5,DATEVALUE(C5)),"CHECK DATE") -> 42318
A6: 5 | B6: US-2015-108966 | C6: 42318 | D6: 10/18/2015 | E6: Standard Class | F6: SO-20335 | G6: Sean O'Donnell | H6: Consumer | I6: United States | J6: Fort Lauderdale | K6: Florida | L6: 33311 | M6: South | N6: OFF-ST-10000760 | O6: Office Supplies | P6: Storage | Q6: Eldon Fold 'N Roll Cart System | R6: 22.368 | S6: 2 | T6: 0.2 | U6: 2.5164 | V6: =IFERROR(IF(ISNUMBER(C6),C6,DATEVALUE(C6)),"CHECK DATE") -> 42318
A7: 6 | B7: CA-2014-115812 | C7: 41888 | D7: 6/14/2014 | E7: Standard Class | F7: BH-11710 | G7: Brosina Hoffman | H7: Consumer | I7: United States | J7: Los Angeles | K7: California | L7: 90032 | M7: West | N7: FUR-FU-10001487 | O7: Furniture | P7: Furnishings | Q7: Eldon Expressions Wood and Plastic Desk Accessories, Cherry Wood | R7: 48.86 | S7: 7 | T7: 0 | U7: 14.1694 | V7: =IFERROR(IF(ISNUMBER(C7),C7,DATEVALUE(C7)),"CHECK DATE") -> 41888
A8: 7 | B8: CA-2014-115812 | C8: 41888 | D8: 6/14/2014 | E8: Standard Class | F8: BH-11710 | G8: Brosina Hoffman | H8: Consumer | I8: United States | J8: Los Angeles | K8: California | L8: 90032 | M8: West | N8: OFF-AR-10002833 | O8: Office Supplies | P8: Art | Q8: Newell 322 | R8: 7.28 | S8: 4 | T8: 0 | U8: 1.9656 | V8: =IFERROR(IF(ISNUMBER(C8),C8,DATEVALUE(C8)),"CHECK DATE") -> 41888
A9: 8 | B9: CA-2014-115812 | C9: 41888 | D9: 6/14/2014 | E9: Standard Class | F9: BH-11710 | G9: Brosina Hoffman | H9: Consumer | I9: United States | J9: Los Angeles | K9: California | L9: 90032 | M9: West | N9: TEC-PH-10002275 | O9: Technology | P9: Phones | Q9: Mitel 5320 IP Phone VoIP phone | R9: 907.152 | S9: 6 | T9: 0.2 | U9: 90.7152 | V9: =IFERROR(IF(ISNUMBER(C9),C9,DATEVALUE(C9)),"CHECK DATE") -> 41888
A10: 9 | B10: CA-2014-115812 | C10: 41888 | D10: 6/14/2014 | E10: Standard Class | F10: BH-11710 | G10: Brosina Hoffman | H10: Consumer | I10: United States | J10: Los Angeles | K10: California | L10: 90032 | M10: West | N10: OFF-BI-10003910 | O10: Office Supplies | P10: Binders | Q10: DXL Angle-View Binders with Locking Rings by Samsill | R10: 18.504 | S10: 3 | T10: 0.2 | U10: 5.7825 | V10: =IFERROR(IF(ISNUMBER(C10),C10,DATEVALUE(C10)),"CHECK DATE") -> 41888
A11: 10 | B11: CA-2014-115812 | C11: 41888 | D11: 6/14/2014 | E11: Standard Class | F11: BH-11710 | G11: Brosina Hoffman | H11: Consumer | I11: United States | J11: Los Angeles | K11: California | L11: 90032 | M11: West | N11: OFF-AP-10002892 | O11: Office Supplies | P11: Appliances | Q11: Belkin F5C206VTEL 6 Outlet Surge | R11: 114.9 | S11: 5 | T11: 0 | U11: 34.47 | V11: =IFERROR(IF(ISNUMBER(C11),C11,DATEVALUE(C11)),"CHECK DATE") -> 41888
A12: 11 | B12: CA-2014-115812 | C12: 41888 | D12: 6/14/2014 | E12: Standard Class | F12: BH-11710 | G12: Brosina Hoffman | H12: Consumer | I12: United States | J12: Los Angeles | K12: California | L12: 90032 | M12: West | N12: FUR-TA-10001539 | O12: Furniture | P12: Tables | Q12: Chromcraft Rectangular Conference Tables | R12: 1706.184 | S12: 9 | T12: 0.2 | U12: 85.3092 | V12: =IFERROR(IF(ISNUMBER(C12),C12,DATEVALUE(C12)),"CHECK DATE") -> 41888
A13: 12 | B13: CA-2014-115812 | C13: 41888 | D13: 6/14/2014 | E13: Standard Class | F13: BH-11710 | G13: Brosina Hoffman | H13: Consumer | I13: United States | J13: Los Angeles | K13: California | L13: 90032 | M13: West | N13: TEC-PH-10002033 | O13: Technology | P13: Phones | Q13: Konftel 250 Conference phone - Charcoal black | R13: 911.424 | S13: 4 | T13: 0.2 | U13: 68.3568 | V13: =IFERROR(IF(ISNUMBER(C13),C13,DATEVALUE(C13)),"CHECK DATE") -> 41888
A14: 13 | B14: CA-2017-114412 | C14: 4/15/2017 | D14: 4/20/2017 | E14: Standard Class | F14: AA-10480 | G14: Andrew Allen | H14: Consumer | I14: United States | J14: Concord | K14: North Carolina | L14: 28027 | M14: South | N14: OFF-PA-10002365 | O14: Office Supplies | P14: Paper | Q14: Xerox 1967 | R14: 15.552 | S14: 3 | T14: 0.2 | U14: 5.4432 | V14: =IFERROR(IF(ISNUMBER(C14),C14,DATEVALUE(C14)),"CHECK DATE") -> CHECK DATE
A15: 14 | B15: CA-2016-161389 | C15: 42502 | D15: 42655 | E15: Standard Class | F15: IM-15070 | G15: Irene Maddox | H15: Consumer | I15: United States | J15: Seattle | K15: Washington | L15: 98103 | M15: West | N15: OFF-BI-10003656 | O15: Office Supplies | P15: Binders | Q15: Fellowes PB200 Plastic Comb Binding Machine | R15: 407.976 | S15: 3 | T15: 0.2 | U15: 132.5922 | V15: =IFERROR(IF(ISNUMBER(C15),C15,DATEVALUE(C15)),"CHECK DATE") -> 42502
A16: 15 | B16: US-2015-118983 | C16: 11/22/2015 | D16: 11/26/2015 | E16: Standard Class | F16: HP-14815 | G16: Harold Pawlan | H16: Home Office | I16: United States | J16: Fort Worth | K16: Texas | L16: 76106 | M16: Central | N16: OFF-AP-10002311 | O16: Office Supplies | P16: Appliances | Q16: Holmes Replacement Filter for HEPA Air Cleaner, Very Large Room, HEPA Filter | R16: 68.81 | S16: 5 | T16: 0.8 | U16: -123.858 | V16: =IFERROR(IF(ISNUMBER(C16),C16,DATEVALUE(C16)),"CHECK DATE") -> CHECK DATE
A17: 16 | B17: US-2015-118983 | C17: 11/22/2015 | D17: 11/26/2015 | E17: Standard Class | F17: HP-14815 | G17: Harold Pawlan | H17: Home Office | I17: United States | J17: Fort Worth | K17: Texas | L17: 76106 | M17: Central | N17: OFF-BI-10000756 | O17: Office Supplies | P17: Binders | Q17: Storex DuraTech Recycled Plastic Frosted Binders | R17: 2.544 | S17: 3 | T17: 0.8 | U17: -3.816 | V17: =IFERROR(IF(ISNUMBER(C17),C17,DATEVALUE(C17)),"CHECK DATE") -> CHECK DATE
A18: 17 | B18: CA-2014-105893 | C18: 41954 | D18: 11/18/2014 | E18: Standard Class | F18: PK-19075 | G18: Pete Kriz | H18: Consumer | I18: United States | J18: Madison | K18: Wisconsin | L18: 53711 | M18: Central | N18: OFF-ST-10004186 | O18: Office Supplies | P18: Storage | Q18: Stur-D-Stor Shelving, Vertical 5-Shelf: 72"H x 36"W x 18 1/2"D | R18: 665.88 | S18: 6 | T18: 0 | U18: 13.3176 | V18: =IFERROR(IF(ISNUMBER(C18),C18,DATEVALUE(C18)),"CHECK DATE") -> 41954
A19: 18 | B19: CA-2014-167164 | C19: 5/13/2014 | D19: 5/15/2014 | E19: Second Class | F19: AG-10270 | G19: Alejandro Grove | H19: Consumer | I19: United States | J19: West Jordan | K19: Utah | L19: 84084 | M19: West | N19: OFF-ST-10000107 | O19: Office Supplies | P19: Storage | Q19: Fellowes Super Stor/Drawer | R19: 55.5 | S19: 2 | T19: 0 | U19: 9.99 | V19: =IFERROR(IF(ISNUMBER(C19),C19,DATEVALUE(C19)),"CHECK DATE") -> CHECK DATE
A20: 19 | B20: CA-2014-143336 | C20: 8/27/2014 | D20: 41648 | E20: Second Class | F20: ZD-21925 | G20: Zuschuss Donatelli | H20: Consumer | I20: United States | J20: San Francisco | K20: California | L20: 94109 | M20: West | N20: OFF-AR-10003056 | O20: Office Supplies | P20: Art | Q20: Newell 341 | R20: 8.56 | S20: 2 | T20: 0 | U20: 2.4824 | V20: =IFERROR(IF(ISNUMBER(C20),C20,DATEVALUE(C20)),"CHECK DATE") -> CHECK DATE
A21: 20 | B21: CA-2014-143336 | C21: 8/27/2014 | D21: 41648 | E21: Second Class | F21: ZD-21925 | G21: Zuschuss Donatelli | H21: Consumer | I21: United States | J21: San Francisco | K21: California | L21: 94109 | M21: West | N21: TEC-PH-10001949 | O21: Technology | P21: Phones | Q21: Cisco SPA 501G IP Phone | R21: 213.48 | S21: 3 | T21: 0.2 | U21: 16.011 | V21: =IFERROR(IF(ISNUMBER(C21),C21,DATEVALUE(C21)),"CHECK DATE") -> CHECK DATE
A22: 21 | B22: CA-2014-143336 | C22: 8/27/2014 | D22: 41648 | E22: Second Class | F22: ZD-21925 | G22: Zuschuss Donatelli | H22: Consumer | I22: United States | J22: San Francisco | K22: California | L22: 94109 | M22: West | N22: OFF-BI-10002215 | O22: Office Supplies | P22: Binders | Q22: Wilson Jones Hanging View Binder, White, 1" | R22: 22.72 | S22: 4 | T22: 0.2 | U22: 7.384 | V22: =IFERROR(IF(ISNUMBER(C22),C22,DATEVALUE(C22)),"CHECK DATE") -> CHECK DATE
A23: 22 | B23: CA-2016-137330 | C23: 42625 | D23: 12/13/2016 | E23: Standard Class | F23: KB-16585 | G23: Ken Black | H23: Corporate | I23: United States | J23: Fremont | K23: Nebraska | L23: 68025 | M23: Central | N23: OFF-AR-10000246 | O23: Office Supplies | P23: Art | Q23: Newell 318 | R23: 19.46 | S23: 7 | T23: 0 | U23: 5.0596 | V23: =IFERROR(IF(ISNUMBER(C23),C23,DATEVALUE(C23)),"CHECK DATE") -> 42625
A24: 23 | B24: CA-2016-137330 | C24: 42625 | D24: 12/13/2016 | E24: Standard Class | F24: KB-16585 | G24: Ken Black | H24: Corporate | I24: United States | J24: Fremont | K24: Nebraska | L24: 68025 | M24: Central | N24: OFF-AP-10001492 | O24: Office Supplies | P24: Appliances | Q24: Acco Six-Outlet Power Strip, 4' Cord Length | R24: 60.34 | S24: 7 | T24: 0 | U24: 15.6884 | V24: =IFERROR(IF(ISNUMBER(C24),C24,DATEVALUE(C24)),"CHECK DATE") -> 42625
A25: 24 | B25: US-2017-156909 | C25: 7/16/2017 | D25: 7/18/2017 | E25: Second Class | F25: SF-20065 | G25: Sandra Flanagan | H25: Consumer | I25: United States | J25: Philadelphia | K25: Pennsylvania | L25: 19140 | M25: East | N25: FUR-CH-10002774 | O25: Furniture | P25: Chairs | Q25: Global Deluxe Stacking Chair, Gray | R25: 71.372 | S25: 2 | T25: 0.3 | U25: -1.0196 | V25: =IFERROR(IF(ISNUMBER(C25),C25,DATEVALUE(C25)),"CHECK DATE") -> CHECK DATE
A26: 25 | B26: CA-2015-106320 | C26: 9/25/2015 | D26: 9/30/2015 | E26: Standard Class | F26: EB-13870 | G26: Emily Burns | H26: Consumer | I26: United States | J26: Orem | K26: Utah | L26: 84057 | M26: West | N26: FUR-TA-10000577 | O26: Furniture | P26: Tables | Q26: Bretford CR4500 Series Slim Rectangular Table | R26: 1044.63 | S26: 3 | T26: 0 | U26: 240.2649 | V26: =IFERROR(IF(ISNUMBER(C26),C26,DATEVALUE(C26)),"CHECK DATE") -> CHECK DATE
A27: 26 | B27: CA-2016-121755 | C27: 1/16/2016 | D27: 1/20/2016 | E27: Second Class | F27: EH-13945 | G27: Eric Hoffmann | H27: Consumer | I27: United States | J27: Los Angeles | K27: California | L27: 90049 | M27: West | N27: OFF-BI-10001634 | O27: Office Supplies | P27: Binders | Q27: Wilson Jones Active Use Binders | R27: 11.648 | S27: 2 | T27: 0.2 | U27: 4.2224 | V27: =IFERROR(IF(ISNUMBER(C27),C27,DATEVALUE(C27)),"CHECK DATE") -> CHECK DATE
A28: 27 | B28: CA-2016-121755 | C28: 1/16/2016 | D28: 1/20/2016 | E28: Second Class | F28: EH-13945 | G28: Eric Hoffmann | H28: Consumer | I28: United States | J28: Los Angeles | K28: California | L28: 90049 | M28: West | N28: TEC-AC-10003027 | O28: Technology | P28: Accessories | Q28: Imation 8GB Mini TravelDrive USB 2.0 Flash Drive | R28: 90.57 | S28: 3 | T28: 0 | U28: 11.7741 | V28: =IFERROR(IF(ISNUMBER(C28),C28,DATEVALUE(C28)),"CHECK DATE") -> CHECK DATE
A29: 28 | B29: US-2015-150630 | C29: 9/17/2015 | D29: 9/21/2015 | E29: Standard Class | F29: TB-21520 | G29: Tracy Blumstein | H29: Consumer | I29: United States | J29: Philadelphia | K29: Pennsylvania | L29: 19140 | M29: East | N29: FUR-BO-10004834 | O29: Furniture | P29: Bookcases | Q29: Riverside Palais Royal Lawyers Bookcase, Royale Cherry Finish | R29: 3083.43 | S29: 7 | T29: 0.5 | U29: -1665.0522 | V29: =IFERROR(IF(ISNUMBER(C29),C29,DATEVALUE(C29)),"CHECK DATE") -> CHECK DATE
A30: 29 | B30: US-2015-150630 | C30: 9/17/2015 | D30: 9/21/2015 | E30: Standard Class | F30: TB-21520 | G30: Tracy Blumstein | H30: Consumer | I30: United States | J30: Philadelphia | K30: Pennsylvania | L30: 19140 | M30: East | N30: OFF-BI-10000474 | O30: Office Supplies | P30: Binders | Q30: Avery Recycled Flexi-View Covers for Binding Systems | R30: 9.618 | S30: 2 | T30: 0.7 | U30: -7.0532 | V30: =IFERROR(IF(ISNUMBER(C30),C30,DATEVALUE(C30)),"CHECK DATE") -> CHECK DATE
A31: 30 | B31: US-2015-150630 | C31: 9/17/2015 | D31: 9/21/2015 | E31: Standard Class | F31: TB-21520 | G31: Tracy Blumstein | H31: Consumer | I31: United States | J31: Philadelphia | K31: Pennsylvania | L31: 19140 | M31: East | N31: FUR-FU-10004848 | O31: Furniture | P31: Furnishings | Q31: Howard Miller 13-3/4" Diameter Brushed Chrome Round Wall Clock | R31: 124.2 | S31: 3 | T31: 0.2 | U31: 15.525 | V31: =IFERROR(IF(ISNUMBER(C31),C31,DATEVALUE(C31)),"CHECK DATE") -> CHECK DATE
A32: 31 | B32: US-2015-150630 | C32: 9/17/2015 | D32: 9/21/2015 | E32: Standard Class | F32: TB-21520 | G32: Tracy Blumstein | H32: Consumer | I32: United States | J32: Philadelphia | K32: Pennsylvania | L32: 19140 | M32: East | N32: OFF-EN-10001509 | O32: Office Supplies | P32: Envelopes | Q32: Poly String Tie Envelopes | R32: 3.264 | S32: 2 | T32: 0.2 | U32: 1.1016 | V32: =IFERROR(IF(ISNUMBER(C32),C32,DATEVALUE(C32)),"CHECK DATE") -> CHECK DATE
A33: 32 | B33: US-2015-150630 | C33: 9/17/2015 | D33: 9/21/2015 | E33: Standard Class | F33: TB-21520 | G33: Tracy Blumstein | H33: Consumer | I33: United States | J33: Philadelphia | K33: Pennsylvania | L33: 19140 | M33: East | N33: OFF-AR-10004042 | O33: Office Supplies | P33: Art | Q33: BOSTON Model 1800 Electric Pencil Sharpeners, Putty/Woodgrain | R33: 86.304 | S33: 6 | T33: 0.2 | U33: 9.7092 | V33: =IFERROR(IF(ISNUMBER(C33),C33,DATEVALUE(C33)),"CHECK DATE") -> CHECK DATE
A34: 33 | B34: US-2015-150630 | C34: 9/17/2015 | D34: 9/21/2015 | E34: Standard Class | F34: TB-21520 | G34: Tracy Blumstein | H34: Consumer | I34: United States | J34: Philadelphia | K34: Pennsylvania | L34: 19140 | M34: East | N34: OFF-BI-10001525 | O34: Office Supplies | P34: Binders | Q34: Acco Pressboard Covers with Storage Hooks, 14 7/8" x 11", Executive Red | R34: 6.858 | S34: 6 | T34: 0.7 | U34: -5.715 | V34: =IFERROR(IF(ISNUMBER(C34),C34,DATEVALUE(C34)),"CHECK DATE") -> CHECK DATE
A35: 34 | B35: US-2015-150630 | C35: 9/17/2015 | D35: 9/21/2015 | E35: Standard Class | F35: TB-21520 | G35: Tracy Blumstein | H35: Consumer | I35: United States | J35: Philadelphia | K35: Pennsylvania | L35: 19140 | M35: East | N35: OFF-AR-10001683 | O35: Office Supplies | P35: Art | Q35: Lumber Crayons | R35: 15.76 | S35: 2 | T35: 0.2 | U35: 3.546 | V35: =IFERROR(IF(ISNUMBER(C35),C35,DATEVALUE(C35)),"CHECK DATE") -> CHECK DATE
A36: 35 | B36: CA-2017-107727 | C36: 10/19/2017 | D36: 10/23/2017 | E36: Second Class | F36: MA-17560 | G36: Matt Abelman | H36: Home Office | I36: United States | J36: Houston | K36: Texas | L36: 77095 | M36: Central | N36: OFF-PA-10000249 | O36: Office Supplies | P36: Paper | Q36: Easy-staple paper | R36: 29.472 | S36: 3 | T36: 0.2 | U36: 9.9468 | V36: =IFERROR(IF(ISNUMBER(C36),C36,DATEVALUE(C36)),"CHECK DATE") -> CHECK DATE
A37: 36 | B37: CA-2016-117590 | C37: 42594 | D37: 42655 | E37: First Class | F37: GH-14485 | G37: Gene Hale | H37: Corporate | I37: United States | J37: Richardson | K37: Texas | L37: 75080 | M37: Central | N37: TEC-PH-10004977 | O37: Technology | P37: Phones | Q37: GE 30524EE4 | R37: 1097.544 | S37: 7 | T37: 0.2 | U37: 123.4737 | V37: =IFERROR(IF(ISNUMBER(C37),C37,DATEVALUE(C37)),"CHECK DATE") -> 42594
A38: 37 | B38: CA-2016-117590 | C38: 42594 | D38: 42655 | E38: First Class | F38: GH-14485 | G38: Gene Hale | H38: Corporate | I38: United States | J38: Richardson | K38: Texas | L38: 75080 | M38: Central | N38: FUR-FU-10003664 | O38: Furniture | P38: Furnishings | Q38: Electrix Architect's Clamp-On Swing Arm Lamp, Black | R38: 190.92 | S38: 5 | T38: 0.6 | U38: -147.963 | V38: =IFERROR(IF(ISNUMBER(C38),C38,DATEVALUE(C38)),"CHECK DATE") -> 42594
A39: 38 | B39: CA-2015-117415 | C39: 12/27/2015 | D39: 12/31/2015 | E39: Standard Class | F39: SN-20710 | G39: Steve Nguyen | H39: Home Office | I39: United States | J39: Houston | K39: Texas | L39: 77041 | M39: Central | N39: OFF-EN-10002986 | O39: Office Supplies | P39: Envelopes | Q39: #10-4 1/8" x 9 1/2" Premium Diagonal Seam Envelopes | R39: 113.328 | S39: 9 | T39: 0.2 | U39: 35.415 | V39: =IFERROR(IF(ISNUMBER(C39),C39,DATEVALUE(C39)),"CHECK DATE") -> CHECK DATE
A40: 39 | B40: CA-2015-117415 | C40: 12/27/2015 | D40: 12/31/2015 | E40: Standard Class | F40: SN-20710 | G40: Steve Nguyen | H40: Home Office | I40: United States | J40: Houston | K40: Texas | L40: 77041 | M40: Central | N40: FUR-BO-10002545 | O40: Furniture | P40: Bookcases | Q40: Atlantic Metals Mobile 3-Shelf Bookcases, Custom Colors | R40: 532.3992 | S40: 3 | T40: 0.32 | U40: -46.9764 | V40: =IFERROR(IF(ISNUMBER(C40),C40,DATEVALUE(C40)),"CHECK DATE") -> CHECK DATE
...

Sheet Monthly Summary
A1: Month | B1: Total Sales | D1: Sales Observation
A2: 41640 | B2: =SUMIFS(Sheet1!R:R,Sheet1!C:C,">="&A2,Sheet1!C:C,"<"&EDATE(A2,1)) -> 19640.427 | D2: Highest Sales Month | E2: 41852
A3: 41671 | B3: =SUMIFS(Sheet1!R:R,Sheet1!C:C,">="&A3,Sheet1!C:C,"<"&EDATE(A3,1)) -> 11833.618 | D3: Highest Sales Value | E3: 26797.763
A4: 41699 | B4: =SUMIFS(Sheet1!R:R,Sheet1!C:C,">="&A4,Sheet1!C:C,"<"&EDATE(A4,1)) -> 7159.67 | C4: Lowest sales | D4: Lowest Sales Month | E4: 41699
A5: 41730 | B5: =SUMIFS(Sheet1!R:R,Sheet1!C:C,">="&A5,Sheet1!C:C,"<"&EDATE(A5,1)) -> 12455.482 | D5: Lowest Sales Value | E5: 7159.67
A6: 41760 | B6: =SUMIFS(Sheet1!R:R,Sheet1!C:C,">="&A6,Sheet1!C:C,"<"&EDATE(A6,1)) -> 15280.411
A7: 41791 | B7: =SUMIFS(Sheet1!R:R,Sheet1!C:C,">="&A7,Sheet1!C:C,"<"&EDATE(A7,1)) -> 11927.849
A8: 41821 | B8: =SUMIFS(Sheet1!R:R,Sheet1!C:C,">="&A8,Sheet1!C:C,"<"&EDATE(A8,1)) -> 10222.428
A9: 41852 | B9: =SUMIFS(Sheet1!R:R,Sheet1!C:C,">="&A9,Sheet1!C:C,"<"&EDATE(A9,1)) -> 26797.763 | C9: Highest sales
A10: 41883 | B10: =SUMIFS(Sheet1!R:R,Sheet1!C:C,">="&A10,Sheet1!C:C,"<"&EDATE(A10,1)) -> 17158.932
A11: 41913 | B11: =SUMIFS(Sheet1!R:R,Sheet1!C:C,">="&A11,Sheet1!C:C,"<"&EDATE(A11,1)) -> 10112.641
A12: 41944 | B12: =SUMIFS(Sheet1!R:R,Sheet1!C:C,">="&A12,Sheet1!C:C,"<"&EDATE(A12,1)) -> 18792.184
A13: 41974 | B13: =SUMIFS(Sheet1!R:R,Sheet1!C:C,">="&A13,Sheet1!C:C,"<"&EDATE(A13,1)) -> 17525.285
